Workbook

Sheet Read Me
A1: Read Me — what is derived and what needs a human
A3: TABS
A4: UK Persona Matrix | B4: The summary Ian asked for. All live formulas.
A5: UK Target Institutions | B5: The denominator. Column D is the only editable column — set Yes/No on every row.
A6: UK Institution Coverage | B6: Institution-by-institution backing data behind the matrix.
A7: Persona Gaps & Priorities | B7: Which target institutions are missing which persona, ranked by how much we already hold there.
A8: Monthly Persona Email Report | B8: Template. Three month blocks. Target pre-set at 2 per persona per month.
A9: Marketing Performance Report | B9: Rolling template: headline metrics, by content type, best vs worst.
A10: Persona - To Review | B10: Contacts whose persona needs a human call.
A11: Zip Import Audit | B11: Where every contact from single_uni.zip landed.
A13: DERIVED, NOT SOURCE DATA
A14: Persona | B14: Filled from job title using rules built from the 6,057 contacts already classified in this workbook. Validated at 98.4% agreement against those. Contacts already carrying a persona were not touched.
A15: Research Tier | B15: Senior / Operational / Academic, from job title. Academic covers professors, fellows and researchers — relevant contacts, but not the buying persona.
A16: Country | B16: Where Region was blank, taken from the email domain: .uk to UK, .edu to USA, .ae to UAE.
A17: Institution (canonical) | B17: Name variants merged, e.g. "The University of Edinburgh" and "University of Edinburgh".
A18: Type (derived) | B18: Organisation type guessed from the name. Wrong in places — correct it in column D of UK Target Institutions.
A19: Snov Status | B19: Contacts imported from single_uni.zip that had no status were set to "valid" on your instruction that the zip contacts are all valid. They are identifiable by Source(s) beginning "single_uni:". No pre-existing status was overwritten.
A20: Alternate Email | B20: Where the same person appeared twice with two addresses, the rows were merged and the second address kept here. No email was discarded.
A22: STILL NEEDS A HUMAN
A23: 1. The target list | B23: Set column D on UK Target Institutions for every row, and add any institution we hold no contacts for. Until then the coverage figure counts only what we already have.
A24: 2. Persona - To Review | B24: Research/Finance hybrids and titles with no functional signal (COO, CEO, Registrar).
A25: 3. Email activity | B25: The blank blocks on the matrix and the two report tabs need the platform export.

Sheet UK Persona Matrix
A1: UK Persona and Audience Matrix
A2: Every figure is a live formula. Edit the target list or fix a persona on a contact sheet and this updates.
A4: INSTITUTION COVERAGE
A5: Relevant UK institutions (target list) | B5: =COUNTIF('UK Target Institutions'!$D$2:$D$727,"Yes") -> 308 | G5: Driven by column D of UK Target Institutions.
A6: Of those, we hold contact data for | B6: =COUNTIFS('UK Target Institutions'!$D$2:$D$727,"Yes",'UK Target Institutions'!$E$2:$E$727,">0") -> 308
A7: Institutions with no contacts at all | B7: =B5-B6 -> 0
A8: Coverage | B8: =IFERROR(B6/B5,"") -> 1
A9: Still to be classified Yes/No | B9: =COUNTIF('UK Target Institutions'!$D$2:$D$727,"Review") -> 0 | G9: Set these in column D of UK Target Institutions.
A11: CONTACTS BY PERSONA — target institutions only
A12: Persona | B12: Contacts | C12: Institutions | D12: Valid email | E12: % of target
A13: Research — total | B13: =SUMIFS('UK Institution Coverage'!$F$2:$F$727,'UK Institution Coverage'!$D$2:$D$727,"Yes") -> 4197 | C13: =COUNTIFS('UK Institution Coverage'!$F$2:$F$727,">0",'UK Institution Coverage'!$D$2:$D$727,"Yes") -> 273 | E13: =IFERROR(C13/$B$5,"") -> 0.88636364
A14: · Senior / executive | B14: =SUMIFS('UK Institution Coverage'!$G$2:$G$727,'UK Institution Coverage'!$D$2:$D$727,"Yes") -> 2016 | C14: =COUNTIFS('UK Institution Coverage'!$G$2:$G$727,">0",'UK Institution Coverage'!$D$2:$D$727,"Yes") -> 236 | E14: =IFERROR(C14/$B$5,"") -> 0.76623377
A15: · Operational | B15: =SUMIFS('UK Institution Coverage'!$H$2:$H$727,'UK Institution Coverage'!$D$2:$D$727,"Yes") -> 1949 | C15: =COUNTIFS('UK Institution Coverage'!$H$2:$H$727,">0",'UK Institution Coverage'!$D$2:$D$727,"Yes") -> 183 | E15: =IFERROR(C15/$B$5,"") -> 0.59415584
A16: · Academic staff | B16: =SUMIFS('UK Institution Coverage'!$I$2:$I$727,'UK Institution Coverage'!$D$2:$D$727,"Yes") -> 198 | C16: =COUNTIFS('UK Institution Coverage'!$I$2:$I$727,">0",'UK Institution Coverage'!$D$2:$D$727,"Yes") -> 84 | E16: =IFERROR(C16/$B$5,"") -> 0.27272727
A17: Finance | B17: =SUMIFS('UK Institution Coverage'!$J$2:$J$727,'UK Institution Coverage'!$D$2:$D$727,"Yes") -> 898 | C17: =COUNTIFS('UK Institution Coverage'!$J$2:$J$727,">0",'UK Institution Coverage'!$D$2:$D$727,"Yes") -> 188 | E17: =IFERROR(C17/$B$5,"") -> 0.61038961
A18: IT/Systems | B18: =SUMIFS('UK Institution Coverage'!$K$2:$K$727,'UK Institution Coverage'!$D$2:$D$727,"Yes") -> 430 | C18: =COUNTIFS('UK Institution Coverage'!$K$2:$K$727,">0",'UK Institution Coverage'!$D$2:$D$727,"Yes") -> 159 | E18: =IFERROR(C18/$B$5,"") -> 0.51623377
A19: Still unclassified | B19: =SUMIFS('UK Institution Coverage'!$L$2:$L$727,'UK Institution Coverage'!$D$2:$D$727,"Yes") -> 200 | C19: =COUNTIFS('UK Institution Coverage'!$L$2:$L$727,">0",'UK Institution Coverage'!$D$2:$D$727,"Yes") -> 66 | E19: =IFERROR(C19/$B$5,"") -> 0.21428571
A20: All UK contacts at target institutions | B20: =SUMIFS('UK Institution Coverage'!$E$2:$E$727,'UK Institution Coverage'!$D$2:$D$727,"Yes") -> 5832
A21: Valid email addresses among them | B21: =SUMIFS('UK Institution Coverage'!$N$2:$N$727,'UK Institution Coverage'!$D$2:$D$727,"Yes") -> 3539
A23: PERSONA GAPS
A24: Holding all three personas | B24: =COUNTIFS('UK Institution Coverage'!$M$2:$M$727,3,'UK Institution Coverage'!$D$2:$D$727,"Yes") -> 138
A25: Holding two | B25: =COUNTIFS('UK Institution Coverage'!$M$2:$M$727,2,'UK Institution Coverage'!$D$2:$D$727,"Yes") -> 48
A26: Holding one | B26: =COUNTIFS('UK Institution Coverage'!$M$2:$M$727,1,'UK Institution Coverage'!$D$2:$D$727,"Yes") -> 110
A27: Average personas per institution | B27: =IFERROR(ROUND(SUMIFS('UK Institution Coverage'!$M$2:$M$727,'UK Institution Coverage'!$D$2:$D$727,"Yes")/B6,2),"") -> 2.01 | G27: Out of 3.
A28: No Research contact | B28: =COUNTIFS('UK Institution Coverage'!$F$2:$F$727,0,'UK Institution Coverage'!$D$2:$D$727,"Yes") -> 35
A29: No Finance contact | B29: =COUNTIFS('UK Institution Coverage'!$J$2:$J$727,0,'UK Institution Coverage'!$D$2:$D$727,"Yes") -> 120
A30: No IT/Systems contact | B30: =COUNTIFS('UK Institution Coverage'!$K$2:$K$727,0,'UK Institution Coverage'!$D$2:$D$727,"Yes") -> 149
A32: ARE THE EMAILS CURRENT AND VALID? (all UK contacts)
A33: Verified valid | B33: =COUNTIFS('Relevant - In CRM valid'!$G$2:$G$4699,"UK",'Relevant - In CRM valid'!$Q$2:$Q$4699,"valid")+COUNTIFS('Relevant - In CRM unknown'!$G$2:$G$253,"UK",'Relevant - In CRM unknown'!$Q$2:$Q$253,"valid")+COUNTIFS('Relevant - IN NOW CRM valid'!$G$2:$G$2328,"UK",'Relevant - IN NOW CRM valid'!$Q$2:$Q$2328,"valid")+COUNTIFS('Relevant - IN NOW CRM unknown'!$G$2:$G$1227,"UK",'Relevant - IN NOW CRM unknown'!$Q$2:$Q$1227,"valid")+COUNTIFS('Relevant - Not CRM not valid'!$G$2:$G$416,"UK",'Relevant - Not CRM not valid'!$Q$2:$Q$416,"valid")+COUNTIFS('Relevant - In CRM not valid'!$G$2:$G$46,"UK",'Relevant - In CRM not valid'!$Q$2:$Q$46,"valid") -> 4034
A34: Unknown | B34: =COUNTIFS('Relevant - In CRM valid'!$G$2:$G$4699,"UK",'Relevant - In CRM valid'!$Q$2:$Q$4699,"unknown")+COUNTIFS('Relevant - In CRM unknown'!$G$2:$G$253,"UK",'Relevant - In CRM unknown'!$Q$2:$Q$253,"unknown")+COUNTIFS('Relevant - IN NOW CRM valid'!$G$2:$G$2328,"UK",'Relevant - IN NOW CRM valid'!$Q$2:$Q$2328,"unknown")+COUNTIFS('Relevant - IN NOW CRM unknown'!$G$2:$G$1227,"UK",'Relevant - IN NOW CRM unknown'!$Q$2:$Q$1227,"unknown")+COUNTIFS('Relevant - Not CRM not valid'!$G$2:$G$416,"UK",'Relevant - Not CRM not valid'!$Q$2:$Q$416,"unknown")+COUNTIFS('Relevant - In CRM not valid'!$G$2:$G$46,"UK",'Relevant - In CRM not valid'!$Q$2:$Q$46,"unknown") -> 1889
A35: Not valid | B35: =COUNTIFS('Relevant - In CRM valid'!$G$2:$G$4699,"UK",'Relevant - In CRM valid'!$Q$2:$Q$4699,"not valid")+COUNTIFS('Relevant - In CRM unknown'!$G$2:$G$253,"UK",'Relevant - In CRM unknown'!$Q$2:$Q$253,"not valid")+COUNTIFS('Relevant - IN NOW CRM valid'!$G$2:$G$2328,"UK",'Relevant - IN NOW CRM valid'!$Q$2:$Q$2328,"not valid")+COUNTIFS('Relevant - IN NOW CRM unknown'!$G$2:$G$1227,"UK",'Relevant - IN NOW CRM unknown'!$Q$2:$Q$1227,"not valid")+COUNTIFS('Relevant - Not CRM not valid'!$G$2:$G$416,"UK",'Relevant - Not CRM not valid'!$Q$2:$Q$416,"not valid")+COUNTIFS('Relevant - In CRM not valid'!$G$2:$G$46,"UK",'Relevant - In CRM not valid'!$Q$2:$Q$46,"not valid") -> 431
A36: No status recorded | B36: =COUNTIFS('Relevant - In CRM valid'!$G$2:$G$4699,"UK",'Relevant - In CRM valid'!$Q$2:$Q$4699,"")+COUNTIFS('Relevant - In CRM unknown'!$G$2:$G$253,"UK",'Relevant - In CRM unknown'!$Q$2:$Q$253,"")+COUNTIFS('Relevant - IN NOW CRM valid'!$G$2:$G$2328,"UK",'Relevant - IN NOW CRM valid'!$Q$2:$Q$2328,"")+COUNTIFS('Relevant - IN NOW CRM unknown'!$G$2:$G$1227,"UK",'Relevant - IN NOW CRM unknown'!$Q$2:$Q$1227,"")+COUNTIFS('Relevant - Not CRM not valid'!$G$2:$G$416,"UK",'Relevant - Not CRM not valid'!$Q$2:$Q$416,"")+COUNTIFS('Relevant - In CRM not valid'!$G$2:$G$46,"UK",'Relevant - In CRM not valid'!$Q$2:$Q$46,"") -> 31
A37: No email address at all | B37: =COUNTIFS('Relevant - In CRM valid'!$G$2:$G$4699,"UK",'Relevant - In CRM valid'!$H$2:$H$4699,"")+COUNTIFS('Relevant - In CRM unknown'!$G$2:$G$253,"UK",'Relevant - In CRM unknown'!$H$2:$H$253,"")+COUNTIFS('Relevant - IN NOW CRM valid'!$G$2:$G$2328,"UK",'Relevant - IN NOW CRM valid'!$H$2:$H$2328,"")+COUNTIFS('Relevant - IN NOW CRM unknown'!$G$2:$G$1227,"UK",'Relevant - IN NOW CRM unknown'!$H$2:$H$1227,"")+COUNTIFS('Relevant - Not CRM not valid'!$G$2:$G$416,"UK",'Relevant - Not CRM not valid'!$H$2:$H$416,"")+COUNTIFS('Relevant - In CRM not valid'!$G$2:$G$46,"UK",'Relevant - In CRM not valid'!$H$2:$H$46,"") -> 32
A39: EMAIL ACTIVITY — fill from the platform export
A40: Persona | B40: Sent last month | C40: Content received | D40: Planned next month | E40: Verdict
A41: Research — senior | E41: =IF(B41="","",IF(B41>3,"OVER-CONTACTED",IF(B41<2,"under-contacted","on target")))
A42: Research — operational | E42: =IF(B42="","",IF(B42>3,"OVER-CONTACTED",IF(B42<2,"under-contacted","on target")))
A43: Finance | E43: =IF(B43="","",IF(B43>3,"OVER-CONTACTED",IF(B43<2,"under-contacted","on target")))
A44: IT/Systems | E44: =IF(B44="","",IF(B44>3,"OVER-CONTACTED",IF(B44<2,"under-contacted","on target")))
A45: Target: 2 emails per persona per month, 3 maximum.

Sheet UK Target Institutions
A1: Institution (canonical) | B1: Name as it appears | C1: Type (derived) | D1: In target list? | E1: Contacts held | F1: Personas held | G1: Coverage status | H1: Decision basis
A2: manchester university | B2: University of Manchester | C2: University | D2: Yes | E2: =IFERROR(INDEX('UK Institution Coverage'!$E$2:$E$727,MATCH($A2,'UK Institution Coverage'!$A$2:$A$727,0)),0) -> 205 | F2: =IFERROR(INDEX('UK Institution Coverage'!$M$2:$M$727,MATCH($A2,'UK Institution Coverage'!$A$2:$A$727,0)),0) -> 3 | G2: =IF($D2<>"Yes","not in target",IF($E2=0,"NO CONTACTS",IF($F2=3,"all 3 personas","partial - "&$F2&" of 3"))) -> all 3 personas | H2: confirmed
A3: king s college london | B3: King's College London | C3: University college | D3: Yes | E3: =IFERROR(INDEX('UK Institution Coverage'!$E$2:$E$727,MATCH($A3,'UK Institution Coverage'!$A$2:$A$727,0)),0) -> 177 | F3: =IFERROR(INDEX('UK Institution Coverage'!$M$2:$M$727,MATCH($A3,'UK Institution Coverage'!$A$2:$A$727,0)),0) -> 3 | G3: =IF($D3<>"Yes","not in target",IF($E3=0,"NO CONTACTS",IF($F3=3,"all 3 personas","partial - "&$F3&" of 3"))) -> all 3 personas | H3: confirmed
A4: coventry university | B4: Coventry University | C4: University | D4: Yes | E4: =IFERROR(INDEX('UK Institution Coverage'!$E$2:$E$727,MATCH($A4,'UK Institution Coverage'!$A$2:$A$727,0)),0) -> 168 | F4: =IFERROR(INDEX('UK Institution Coverage'!$M$2:$M$727,MATCH($A4,'UK Institution Coverage'!$A$2:$A$727,0)),0) -> 3 | G4: =IF($D4<>"Yes","not in target",IF($E4=0,"NO CONTACTS",IF($F4=3,"all 3 personas","partial - "&$F4&" of 3"))) -> all 3 personas | H4: confirmed
A5: sussex university | B5: University of Sussex | C5: University | D5: Yes | E5: =IFERROR(INDEX('UK Institution Coverage'!$E$2:$E$727,MATCH($A5,'UK Institution Coverage'!$A$2:$A$727,0)),0) -> 158 | F5: =IFERROR(INDEX('UK Institution Coverage'!$M$2:$M$727,MATCH($A5,'UK Institution Coverage'!$A$2:$A$727,0)),0) -> 3 | G5: =IF($D5<>"Yes","not in target",IF($E5=0,"NO CONTACTS",IF($F5=3,"all 3 personas","partial - "&$F5&" of 3"))) -> all 3 personas | H5: confirmed
A6: edinburgh university | B6: University of Edinburgh | C6: University | D6: Yes | E6: =IFERROR(INDEX('UK Institution Coverage'!$E$2:$E$727,MATCH($A6,'UK Institution Coverage'!$A$2:$A$727,0)),0) -> 131 | F6: =IFERROR(INDEX('UK Institution Coverage'!$M$2:$M$727,MATCH($A6,'UK Institution Coverage'!$A$2:$A$727,0)),0) -> 3 | G6: =IF($D6<>"Yes","not in target",IF($E6=0,"NO CONTACTS",IF($F6=3,"all 3 personas","partial - "&$F6&" of 3"))) -> all 3 personas | H6: confirmed
A7: liverpool university | B7: University of Liverpool | C7: University | D7: Yes | E7: =IFERROR(INDEX('UK Institution Coverage'!$E$2:$E$727,MATCH($A7,'UK Institution Coverage'!$A$2:$A$727,0)),0) -> 124 | F7: =IFERROR(INDEX('UK Institution Coverage'!$M$2:$M$727,MATCH($A7,'UK Institution Coverage'!$A$2:$A$727,0)),0) -> 3 | G7: =IF($D7<>"Yes","not in target",IF($E7=0,"NO CONTACTS",IF($F7=3,"all 3 personas","partial - "&$F7&" of 3"))) -> all 3 personas | H7: confirmed
A8: sheffield university | B8: The University of Sheffield | C8: University | D8: Yes | E8: =IFERROR(INDEX('UK Institution Coverage'!$E$2:$E$727,MATCH($A8,'UK Institution Coverage'!$A$2:$A$727,0)),0) -> 115 | F8: =IFERROR(INDEX('UK Institution Coverage'!$M$2:$M$727,MATCH($A8,'UK Institution Coverage'!$A$2:$A$727,0)),0) -> 3 | G8: =IF($D8<>"Yes","not in target",IF($E8=0,"NO CONTACTS",IF($F8=3,"all 3 personas","partial - "&$F8&" of 3"))) -> all 3 personas | H8: confirmed
A9: manchester metropolitan university | B9: The Manchester Metropolitan University | C9: University | D9: Yes | E9: =IFERROR(INDEX('UK Institution Coverage'!$E$2:$E$727,MATCH($A9,'UK Institution Coverage'!$A$2:$A$727,0)),0) -> 109 | F9: =IFERROR(INDEX('UK Institution Coverage'!$M$2:$M$727,MATCH($A9,'UK Institution Coverage'!$A$2:$A$727,0)),0) -> 3 | G9: =IF($D9<>"Yes","not in target",IF($E9=0,"NO CONTACTS",IF($F9=3,"all 3 personas","partial - "&$F9&" of 3"))) -> all 3 personas | H9: confirmed
A10: york university | B10: University of York | C10: University | D10: Yes | E10: =IFERROR(INDEX('UK Institution Coverage'!$E$2:$E$727,MATCH($A10,'UK Institution Coverage'!$A$2:$A$727,0)),0) -> 92 | F10: =IFERROR(INDEX('UK Institution Coverage'!$M$2:$M$727,MATCH($A10,'UK Institution Coverage'!$A$2:$A$727,0)),0) -> 3 | G10: =IF($D10<>"Yes","not in target",IF($E10=0,"NO CONTACTS",IF($F10=3,"all 3 personas","partial - "&$F10&" of 3"))) -> all 3 personas | H10: confirmed
A11: cardiff university | B11: Cardiff University | C11: University | D11: Yes | E11: =IFERROR(INDEX('UK Institution Coverage'!$E$2:$E$727,MATCH($A11,'UK Institution Coverage'!$A$2:$A$727,0)),0) -> 86 | F11: =IFERROR(INDEX('UK Institution Coverage'!$M$2:$M$727,MATCH($A11,'UK Institution Coverage'!$A$2:$A$727,0)),0) -> 3 | G11: =IF($D11<>"Yes","not in target",IF($E11=0,"NO CONTACTS",IF($F11=3,"all 3 personas","partial - "&$F11&" of 3"))) -> all 3 personas | H11: confirmed
A12: exeter university | B12: University Of Exeter | C12: University | D12: Yes | E12: =IFERROR(INDEX('UK Institution Coverage'!$E$2:$E$727,MATCH($A12,'UK Institution Coverage'!$A$2:$A$727,0)),0) -> 95 | F12: =IFERROR(INDEX('UK Institution Coverage'!$M$2:$M$727,MATCH($A12,'UK Institution Coverage'!$A$2:$A$727,0)),0) -> 3 | G12: =IF($D12<>"Yes","not in target",IF($E12=0,"NO CONTACTS",IF($F12=3,"all 3 personas","partial - "&$F12&" of 3"))) -> all 3 personas | H12: confirmed
A13: newcastle university | B13: Newcastle University | C13: University | D13: Yes | E13: =IFERROR(INDEX('UK Institution Coverage'!$E$2:$E$727,MATCH($A13,'UK Institution Coverage'!$A$2:$A$727,0)),0) -> 87 | F13: =IFERROR(INDEX('UK Institution Coverage'!$M$2:$M$727,MATCH($A13,'UK Institution Coverage'!$A$2:$A$727,0)),0) -> 2 | G13: =IF($D13<>"Yes","not in target",IF($E13=0,"NO CONTACTS",IF($F13=3,"all 3 personas","partial - "&$F13&" of 3"))) -> partial - 2 of 3 | H13: confirmed
... A727: yorkshire universities | B727: Yorkshire Universities | C727: University | D727: Yes | E727: =IFERROR(INDEX('UK Institution Coverage'!$E$2:$E$727,MATCH($A727,'UK Institution Coverage'!$A$2:$A$727,0)),0) -> 1 | F727: =IFERROR(INDEX('UK Institution Coverage'!$M$2:$M$727,MATCH($A727,'UK Institution Coverage'!$A$2:$A$727,0)),0) -> 0 | G727: =IF($D727<>"Yes","not in target",IF($E727=0,"NO CONTACTS",IF($F727=3,"all 3 personas","partial - "&$F727&" of 3"))) -> partial - 0 of 3 | H727: confirmed
A729: Column D is the only column to edit. Set Yes / No for every row, including the "Review" ones. Add any institution we hold no contacts for as a new row at the bottom with D = Yes — the matrix will count it as a gap.

Sheet UK Institution Coverage
A1: Institution (canonical) | B1: Name as it appears | C1: Type | D1: In target list | E1: Contacts | F1: Research | G1: · Senior | H1: · Operational | I1: · Academic | J1: Finance | K1: IT/Systems | L1: Unclassified | M1: Personas held | N1: Valid emails | O1: Missing personas
A2: manchester university | B2: University of Manchester | C2: University | D2: =IFERROR(INDEX('UK Target Institutions'!$D$2:$D$727,MATCH($A2,'UK Target Institutions'!$A$2:$A$727,0)),"") -> Yes | E2: =COUNTIFS('Relevant - In CRM valid'!$T$2:$T$4699,$A2,'Relevant - In CRM valid'!$G$2:$G$4699,"UK")+COUNTIFS('Relevant - In CRM unknown'!$T$2:$T$253,$A2,'Relevant - In CRM unknown'!$G$2:$G$253,"UK")+COUNTIFS('Relevant - IN NOW CRM valid'!$T$2:$T$2328,$A2,'Relevant - IN NOW CRM valid'!$G$2:$G$2328,"UK")+COUNTIFS('Relevant - IN NOW CRM unknown'!$T$2:$T$1227,$A2,'Relevant - IN NOW CRM unknown'!$G$2:$G$1227,"UK")+COUNTIFS('Relevant - Not CRM not valid'!$T$2:$T$416,$A2,'Relevant - Not CRM not valid'!$G$2:$G$416,"UK")+COUNTIFS('Relevant - In CRM not valid'!$T$2:$T$46,$A2,'Relevant - In CRM not valid'!$G$2:$G$46,"UK") -> 205 | F2: =COUNTIFS('Relevant - In CRM valid'!$T$2:$T$4699,$A2,'Relevant - In CRM valid'!$G$2:$G$4699,"UK",'Relevant - In CRM valid'!$M$2:$M$4699,"Research")+COUNTIFS('Relevant - In CRM unknown'!$T$2:$T$253,$A2,'Relevant - In CRM unknown'!$G$2:$G$253,"UK",'Relevant - In CRM unknown'!$M$2:$M$253,"Research")+COUNTIFS('Relevant - IN NOW CRM valid'!$T$2:$T$2328,$A2,'Relevant - IN NOW CRM valid'!$G$2:$G$2328,"UK",'Relevant - IN NOW CRM valid'!$M$2:$M$2328,"Research")+COUNTIFS('Relevant - IN NOW CRM unknown'!$T$2:$T$1227,$A2,'Relevant - IN NOW CRM unknown'!$G$2:$G$1227,"UK",'Relevant - IN NOW CRM unknown'!$M$2:$M$1227,"Research")+COUNTIFS('Relevant - Not CRM not valid'!$T$2:$T$416,$A2,'Relevant - Not CRM not valid'!$G$2:$G$416,"UK",'Relevant - Not CRM not valid'!$M$2:$M$416,"Research")+COUNTIFS('Relevant - In CRM not valid'!$T$2:$T$46,$A2,'Relevant - In CRM not valid'!$G$2:$G$46,"UK",'Relevant - In CRM not valid'!$M$2:$M$46,"Research") -> 156 | G2: =COUNTIFS('Relevant - In CRM valid'!$T$2:$T$4699,$A2,'Relevant - In CRM valid'!$G$2:$G$4699,"UK",'Relevant - In CRM valid'!$M$2:$M$4699,"Research",'Relevant - In CRM valid'!$R$2:$R$4699,"Senior")+COUNTIFS('Relevant - In CRM unknown'!$T$2:$T$253,$A2,'Relevant - In CRM unknown'!$G$2:$G$253,"UK",'Relevant - In CRM unknown'!$M$2:$M$253,"Research",'Relevant - In CRM unknown'!$R$2:$R$253,"Senior")+COUNTIFS('Relevant - IN NOW CRM valid'!$T$2:$T$2328,$A2,'Relevant - IN NOW CRM valid'!$G$2:$G$2328,"UK",'Relevant - IN NOW CRM valid'!$M$2:$M$2328,"Research",'Relevant - IN NOW CRM valid'!$R$2:$R$2328,"Senior")+COUNTIFS('Relevant - IN NOW CRM unknown'!$T$2:$T$1227,$A2,'Relevant - IN NOW CRM unknown'!$G$2:$G$1227,"UK",'Relevant - IN NOW CRM unknown'!$M$2:$M$1227,"Research",'Relevant - IN NOW CRM unknown'!$R$2:$R$1227,"Senior")+COUNTIFS('Relevant - Not CRM not valid'!$T$2:$T$416,$A2,'Relevant - Not CRM not valid'!$G$2:$G$416,"UK",'Relevant - Not CRM not valid'!$M$2:$M$416,"Research",'Relevant - Not CRM not valid'!$R$2:$R$416,"Senior")+COUNTIFS('Relevant - In CRM not valid'!$T$2:$T$46,$A2,'Relevant - In CRM not valid'!$G$2:$G$46,"UK",'Relevant - In CRM not valid'!$M$2:$M$46,"Research",'Relevant - In CRM not valid'!$R$2:$R$46,"Senior") -> 30 | H2: =COUNTIFS('Relevant - In CRM valid'!$T$2:$T$4699,$A2,'Relevant - In CRM valid'!$G$2:$G$4699,"UK",'Relevant - In CRM valid'!$M$2:$M$4699,"Research",'Relevant - In CRM valid'!$R$2:$R$4699,"Operational")+COUNTIFS('Relevant - In CRM unknown'!$T$2:$T$253,$A2,'Relevant - In CRM unknown'!$G$2:$G$253,"UK",'Relevant - In CRM unknown'!$M$2:$M$253,"Research",'Relevant - In CRM unknown'!$R$2:$R$253,"Operational")+COUNTIFS('Relevant - IN NOW CRM valid'!$T$2:$T$2328,$A2,'Relevant - IN NOW CRM valid'!$G$2:$G$2328,"UK",'Relevant - IN NOW CRM valid'!$M$2:$M$2328,"Research",'Relevant - IN NOW CRM valid'!$R$2:$R$2328,"Operational")+COUNTIFS('Relevant - IN NOW CRM unknown'!$T$2:$T$1227,$A2,'Relevant - IN NOW CRM unknown'!$G$2:$G$1227,"UK",'Relevant - IN NOW CRM unknown'!$M$2:$M$1227,"Research",'Relevant - IN NOW CRM unknown'!$R$2:$R$1227,"Operational")+COUNTIFS('Relevant - Not CRM not valid'!$T$2:$T$416,$A2,'Relevant - Not CRM not valid'!$G$2:$G$416,"UK",'Relevant - Not CRM not valid'!$M$2:$M$416,"Research",'Relevant - Not CRM not valid'!$R$2:$R$416,"Operational")+COUNTIFS('Relevant - In CRM not valid'!$T$2:$T$46,$A2,'Relevant - In CRM not valid'!$G$2:$G$46,"UK",'Relevant - In CRM not valid'!$M$2:$M$46,"Research",'Relevant - In CRM not valid'!$R$2:$R$46,"Operational") -> 118 | I2: =COUNTIFS('Relevant - In CRM valid'!$T$2:$T$4699,$A2,'Relevant - In CRM valid'!$G$2:$G$4699,"UK",'Relevant - In CRM valid'!$M$2:$M$4699,"Research",'Relevant - In CRM valid'!$R$2:$R$4699,"Academic")+COUNTIFS('Relevant - In CRM unknown'!$T$2:$T$253,$A2,'Relevant - In CRM unknown'!$G$2:$G$253,"UK",'Relevant - In CRM unknown'!$M$2:$M$253,"Research",'Relevant - In CRM unknown'!$R$2:$R$253,"Academic")+COUNTIFS('Relevant - IN NOW CRM valid'!$T$2:$T$2328,$A2,'Relevant - IN NOW CRM valid'!$G$2:$G$2328,"UK",'Relevant - IN NOW CRM valid'!$M$2:$M$2328,"Research",'Relevant - IN NOW CRM valid'!$R$2:$R$2328,"Academic")+COUNTIFS('Relevant - IN NOW CRM unknown'!$T$2:$T$1227,$A2,'Relevant - IN NOW CRM unknown'!$G$2:$G$1227,"UK",'Relevant - IN NOW CRM unknown'!$M$2:$M$1227,"Research",'Relevant - IN NOW CRM unknown'!$R$2:$R$1227,"Academic")+COUNTIFS('Relevant - Not CRM not valid'!$T$2:$T$416,$A2,'Relevant - Not CRM not valid'!$G$2:$G$416,"UK",'Relevant - Not CRM not valid'!$M$2:$M$416,"Research",'Relevant - Not CRM not valid'!$R$2:$R$416,"Academic")+COUNTIFS('Relevant - In CRM not valid'!$T$2:$T$46,$A2,'Relevant - In CRM not valid'!$G$2:$G$46,"UK",'Relevant - In CRM not valid'!$M$2:$M$46,"Research",'Relevant - In CRM not valid'!$R$2:$R$46,"Academic") -> 4 | J2: =COUNTIFS('Relevant - In CRM valid'!$T$2:$T$4699,$A2,'Relevant - In CRM valid'!$G$2:$G$4699,"UK",'Relevant - In CRM valid'!$M$2:$M$4699,"Finance")+COUNTIFS('Relevant - In CRM unknown'!$T$2:$T$253,$A2,'Relevant - In CRM unknown'!$G$2:$G$253,"UK",'Relevant - In CRM unknown'!$M$2:$M$253,"Finance")+COUNTIFS('Relevant - IN NOW CRM valid'!$T$2:$T$2328,$A2,'Relevant - IN NOW CRM valid'!$G$2:$G$2328,"UK",'Relevant - IN NOW CRM valid'!$M$2:$M$2328,"Finance")+COUNTIFS('Relevant - IN NOW CRM unknown'!$T$2:$T$1227,$A2,'Relevant - IN NOW CRM unknown'!$G$2:$G$1227,"UK",'Relevant - IN NOW CRM unknown'!$M$2:$M$1227,"Finance")+COUNTIFS('Relevant - Not CRM not valid'!$T$2:$T$416,$A2,'Relevant - Not CRM not valid'!$G$2:$G$416,"UK",'Relevant - Not CRM not valid'!$M$2:$M$416,"Finance")+COUNTIFS('Relevant - In CRM not valid'!$T$2:$T$46,$A2,'Relevant - In CRM not valid'!$G$2:$G$46,"UK",'Relevant - In CRM not valid'!$M$2:$M$46,"Finance") -> 39 | K2: =COUNTIFS('Relevant - In CRM valid'!$T$2:$T$4699,$A2,'Relevant - In CRM valid'!$G$2:$G$4699,"UK",'Relevant - In CRM valid'!$M$2:$M$4699,"IT/Systems")+COUNTIFS('Relevant - In CRM unknown'!$T$2:$T$253,$A2,'Relevant - In CRM unknown'!$G$2:$G$253,"UK",'Relevant - In CRM unknown'!$M$2:$M$253,"IT/Systems")+COUNTIFS('Relevant - IN NOW CRM valid'!$T$2:$T$2328,$A2,'Relevant - IN NOW CRM valid'!$G$2:$G$2328,"UK",'Relevant - IN NOW CRM valid'!$M$2:$M$2328,"IT/Systems")+COUNTIFS('Relevant - IN NOW CRM unknown'!$T$2:$T$1227,$A2,'Relevant - IN NOW CRM unknown'!$G$2:$G$1227,"UK",'Relevant - IN NOW CRM unknown'!$M$2:$M$1227,"IT/Systems")+COUNTIFS('Relevant - Not CRM not valid'!$T$2:$T$416,$A2,'Relevant - Not CRM not valid'!$G$2:$G$416,"UK",'Relevant - Not CRM not valid'!$M$2:$M$416,"IT/Systems")+COUNTIFS('Relevant - In CRM not valid'!$T$2:$T$46,$A2,'Relevant - In CRM not valid'!$G$2:$G$46,"UK",'Relevant - In CRM not valid'!$M$2:$M$46,"IT/Systems") -> 8 | L2: =COUNTIFS('Relevant - In CRM valid'!$T$2:$T$4699,$A2,'Relevant - In CRM valid'!$G$2:$G$4699,"UK",'Relevant - In CRM valid'!$M$2:$M$4699,"")+COUNTIFS('Relevant - In CRM unknown'!$T$2:$T$253,$A2,'Relevant - In CRM unknown'!$G$2:$G$253,"UK",'Relevant - In CRM unknown'!$M$2:$M$253,"")+COUNTIFS('Relevant - IN NOW CRM valid'!$T$2:$T$2328,$A2,'Relevant - IN NOW CRM valid'!$G$2:$G$2328,"UK",'Relevant - IN NOW CRM valid'!$M$2:$M$2328,"")+COUNTIFS('Relevant - IN NOW CRM unknown'!$T$2:$T$1227,$A2,'Relevant - IN NOW CRM unknown'!$G$2:$G$1227,"UK",'Relevant - IN NOW CRM unknown'!$M$2:$M$1227,"")+COUNTIFS('Relevant - Not CRM not valid'!$T$2:$T$416,$A2,'Relevant - Not CRM not valid'!$G$2:$G$416,"UK",'Relevant - Not CRM not valid'!$M$2:$M$416,"")+COUNTIFS('Relevant - In CRM not valid'!$T$2:$T$46,$A2,'Relevant - In CRM not valid'!$G$2:$G$46,"UK",'Relevant - In CRM not valid'!$M$2:$M$46,"") -> 2 | M2: =(F2>0)+(J2>0)+(K2>0) -> 3 | N2: =COUNTIFS('Relevant - In CRM valid'!$T$2:$T$4699,$A2,'Relevant - In CRM valid'!$G$2:$G$4699,"UK",'Relevant - In CRM valid'!$Q$2:$Q$4699,"valid")+COUNTIFS('Relevant - In CRM unknown'!$T$2:$T$253,$A2,'Relevant - In CRM unknown'!$G$2:$G$253,"UK",'Relevant - In CRM unknown'!$Q$2:$Q$253,"valid")+COUNTIFS('Relevant - IN NOW CRM valid'!$T$2:$T$2328,$A2,'Relevant - IN NOW CRM valid'!$G$2:$G$2328,"UK",'Relevant - IN NOW CRM valid'!$Q$2:$Q$2328,"valid")+COUNTIFS('Relevant - IN NOW CRM unknown'!$T$2:$T$1227,$A2,'Relevant - IN NOW CRM unknown'!$G$2:$G$1227,"UK",'Relevant - IN NOW CRM unknown'!$Q$2:$Q$1227,"valid")+COUNTIFS('Relevant - Not CRM not valid'!$T$2:$T$416,$A2,'Relevant - Not CRM not valid'!$G$2:$G$416,"UK",'Relevant - Not CRM not valid'!$Q$2:$Q$416,"valid")+COUNTIFS('Relevant - In CRM not valid'!$T$2:$T$46,$A2,'Relevant - In CRM not valid'!$G$2:$G$46,"UK",'Relevant - In CRM not valid'!$Q$2:$Q$46,"valid") -> 121 | O2: =IF(F2=0,"Research ","")&IF(J2=0,"Finance ","")&IF(K2=0,"IT/Systems","")
A3: king s college london | B3: King's College London | C3: University college | D3: =IFERROR(INDEX('UK Target Institutions'!$D$2:$D$727,MATCH($A3,'UK Target Institutions'!$A$2:$A$727,0)),"") -> Yes | E3: =COUNTIFS('Relevant - In CRM valid'!$T$2:$T$4699,$A3,'Relevant - In CRM valid'!$G$2:$G$4699,"UK")+COUNTIFS('Relevant - In CRM unknown'!$T$2:$T$253,$A3,'Relevant - In CRM unknown'!$G$2:$G$253,"UK")+COUNTIFS('Relevant - IN NOW CRM valid'!$T$2:$T$2328,$A3,'Relevant - IN NOW CRM valid'!$G$2:$G$2328,"UK")+COUNTIFS('Relevant - IN NOW CRM unknown'!$T$2:$T$1227,$A3,'Relevant - IN NOW CRM unknown'!$G$2:$G$1227,"UK")+COUNTIFS('Relevant - Not CRM not valid'!$T$2:$T$416,$A3,'Relevant - Not CRM not valid'!$G$2:$G$416,"UK")+COUNTIFS('Relevant - In CRM not valid'!$T$2:$T$46,$A3,'Relevant - In CRM not valid'!$G$2:$G$46,"UK") -> 177 | F3: =COUNTIFS('Relevant - In CRM valid'!$T$2:$T$4699,$A3,'Relevant - In CRM valid'!$G$2:$G$4699,"UK",'Relevant - In CRM valid'!$M$2:$M$4699,"Research")+COUNTIFS('Relevant - In CRM unknown'!$T$2:$T$253,$A3,'Relevant - In CRM unknown'!$G$2:$G$253,"UK",'Relevant - In CRM unknown'!$M$2:$M$253,"Research")+COUNTIFS('Relevant - IN NOW CRM valid'!$T$2:$T$2328,$A3,'Relevant - IN NOW CRM valid'!$G$2:$G$2328,"UK",'Relevant - IN NOW CRM valid'!$M$2:$M$2328,"Research")+COUNTIFS('Relevant - IN NOW CRM unknown'!$T$2:$T$1227,$A3,'Relevant - IN NOW CRM unknown'!$G$2:$G$1227,"UK",'Relevant - IN NOW CRM unknown'!$M$2:$M$1227,"Research")+COUNTIFS('Relevant - Not CRM not valid'!$T$2:$T$416,$A3,'Relevant - Not CRM not valid'!$G$2:$G$416,"UK",'Relevant - Not CRM not valid'!$M$2:$M$416,"Research")+COUNTIFS('Relevant - In CRM not valid'!$T$2:$T$46,$A3,'Relevant - In CRM not valid'!$G$2:$G$46,"UK",'Relevant - In CRM not valid'!$M$2:$M$46,"Research") -> 173 | G3: =COUNTIFS('Relevant - In CRM valid'!$T$2:$T$4699,$A3,'Relevant - In CRM valid'!$G$2:$G$4699,"UK",'Relevant - In CRM valid'!$M$2:$M$4699,"Research",'Relevant - In CRM valid'!$R$2:$R$4699,"Senior")+COUNTIFS('Relevant - In CRM unknown'!$T$2:$T$253,$A3,'Relevant - In CRM unknown'!$G$2:$G$253,"UK",'Relevant - In CRM unknown'!$M$2:$M$253,"Research",'Relevant - In CRM unknown'!$R$2:$R$253,"Senior")+COUNTIFS('Relevant - IN NOW CRM valid'!$T$2:$T$2328,$A3,'Relevant - IN NOW CRM valid'!$G$2:$G$2328,"UK",'Relevant - IN NOW CRM valid'!$M$2:$M$2328,"Research",'Relevant - IN NOW CRM valid'!$R$2:$R$2328,"Senior")+COUNTIFS('Relevant - IN NOW CRM unknown'!$T$2:$T$1227,$A3,'Relevant - IN NOW CRM unknown'!$G$2:$G$1227,"UK",'Relevant - IN NOW CRM unknown'!$M$2:$M$1227,"Research",'Relevant - IN NOW CRM unknown'!$R$2:$R$1227,"Senior")+COUNTIFS('Relevant - Not CRM not valid'!$T$2:$T$416,$A3,'Relevant - Not CRM not valid'!$G$2:$G$416,"UK",'Relevant - Not CRM not valid'!$M$2:$M$416,"Research",'Relevant - Not CRM not valid'!$R$2:$R$416,"Senior")+COUNTIFS('Relevant - In CRM not valid'!$T$2:$T$46,$A3,'Relevant - In CRM not valid'!$G$2:$G$46,"UK",'Relevant - In CRM not valid'!$M$2:$M$46,"Research",'Relevant - In CRM not valid'!$R$2:$R$46,"Senior") -> 46 | H3: =COUNTIFS('Relevant - In CRM valid'!$T$2:$T$4699,$A3,'Relevant - In CRM valid'!$G$2:$G$4699,"UK",'Relevant - In CRM valid'!$M$2:$M$4699,"Research",'Relevant - In CRM valid'!$R$2:$R$4699,"Operational")+COUNTIFS('Relevant - In CRM unknown'!$T$2:$T$253,$A3,'Relevant - In CRM unknown'!$G$2:$G$253,"UK",'Relevant - In CRM unknown'!$M$2:$M$253,"Research",'Relevant - In CRM unknown'!$R$2:$R$253,"Operational")+COUNTIFS('Relevant - IN NOW CRM valid'!$T$2:$T$2328,$A3,'Relevant - IN NOW CRM valid'!$G$2:$G$2328,"UK",'Relevant - IN NOW CRM valid'!$M$2:$M$2328,"Research",'Relevant - IN NOW CRM valid'!$R$2:$R$2328,"Operational")+COUNTIFS('Relevant - IN NOW CRM unknown'!$T$2:$T$1227,$A3,'Relevant - IN NOW CRM unknown'!$G$2:$G$1227,"UK",'Relevant - IN NOW CRM unknown'!$M$2:$M$1227,"Research",'Relevant - IN NOW CRM unknown'!$R$2:$R$1227,"Operational")+COUNTIFS('Relevant - Not CRM not valid'!$T$2:$T$416,$A3,'Relevant - Not CRM not valid'!$G$2:$G$416,"UK",'Relevant - Not CRM not valid'!$M$2:$M$416,"Research",'Relevant - Not CRM not valid'!$R$2:$R$416,"Operational")+COUNTIFS('Relevant - In CRM not valid'!$T$2:$T$46,$A3,'Relevant - In CRM not valid'!$G$2:$G$46,"UK",'Relevant - In CRM not valid'!$M$2:$M$46,"Research",'Relevant - In CRM not valid'!$R$2:$R$46,"Operational") -> 117 | I3: =COUNTIFS('Relevant - In CRM valid'!$T$2:$T$4699,$A3,'Relevant - In CRM valid'!$G$2:$G$4699,"UK",'Relevant - In CRM valid'!$M$2:$M$4699,"Research",'Relevant - In CRM valid'!$R$2:$R$4699,"Academic")+COUNTIFS('Relevant - In CRM unknown'!$T$2:$T$253,$A3,'Relevant - In CRM unknown'!$G$2:$G$253,"UK",'Relevant - In CRM unknown'!$M$2:$M$253,"Research",'Relevant - In CRM unknown'!$R$2:$R$253,"Academic")+COUNTIFS('Relevant - IN NOW CRM valid'!$T$2:$T$2328,$A3,'Relevant - IN NOW CRM valid'!$G$2:$G$2328,"UK",'Relevant - IN NOW CRM valid'!$M$2:$M$2328,"Research",'Relevant - IN NOW CRM valid'!$R$2:$R$2328,"Academic")+COUNTIFS('Relevant - IN NOW CRM unknown'!$T$2:$T$1227,$A3,'Relevant - IN NOW CRM unknown'!$G$2:$G$1227,"UK",'Relevant - IN NOW CRM unknown'!$M$2:$M$1227,"Research",'Relevant - IN NOW CRM unknown'!$R$2:$R$1227,"Academic")+COUNTIFS('Relevant - Not CRM not valid'!$T$2:$T$416,$A3,'Relevant - Not CRM not valid'!$G$2:$G$416,"UK",'Relevant - Not CRM not valid'!$M$2:$M$416,"Research",'Relevant - Not CRM not valid'!$R$2:$R$416,"Academic")+COUNTIFS('Relevant - In CRM not valid'!$T$2:$T$46,$A3,'Relevant - In CRM not valid'!$G$2:$G$46,"UK",'Relevant - In CRM not valid'!$M$2:$M$46,"Research",'Relevant - In CRM not valid'!$R$2:$R$46,"Academic") -> 10 | J3: =COUNTIFS('Relevant - In CRM valid'!$T$2:$T$4699,$A3,'Relevant - In CRM valid'!$G$2:$G$4699,"UK",'Relevant - In CRM valid'!$M$2:$M$4699,"Finance")+COUNTIFS('Relevant - In CRM unknown'!$T$2:$T$253,$A3,'Relevant - In CRM unknown'!$G$2:$G$253,"UK",'Relevant - In CRM unknown'!$M$2:$M$253,"Finance")+COUNTIFS('Relevant - IN NOW CRM valid'!$T$2:$T$2328,$A3,'Relevant - IN NOW CRM valid'!$G$2:$G$2328,"UK",'Relevant - IN NOW CRM valid'!$M$2:$M$2328,"Finance")+COUNTIFS('Relevant - IN NOW CRM unknown'!$T$2:$T$1227,$A3,'Relevant - IN NOW CRM unknown'!$G$2:$G$1227,"UK",'Relevant - IN NOW CRM unknown'!$M$2:$M$1227,"Finance")+COUNTIFS('Relevant - Not CRM not valid'!$T$2:$T$416,$A3,'Relevant - Not CRM not valid'!$G$2:$G$416,"UK",'Relevant - Not CRM not valid'!$M$2:$M$416,"Finance")+COUNTIFS('Relevant - In CRM not valid'!$T$2:$T$46,$A3,'Relevant - In CRM not valid'!$G$2:$G$46,"UK",'Relevant - In CRM not valid'!$M$2:$M$46,"Finance") -> 2 | K3: =COUNTIFS('Relevant - In CRM valid'!$T$2:$T$4699,$A3,'Relevant - In CRM valid'!$G$2:$G$4699,"UK",'Relevant - In CRM valid'!$M$2:$M$4699,"IT/Systems")+COUNTIFS('Relevant - In CRM unknown'!$T$2:$T$253,$A3,'Relevant - In CRM unknown'!$G$2:$G$253,"UK",'Relevant - In CRM unknown'!$M$2:$M$253,"IT/Systems")+COUNTIFS('Relevant - IN NOW CRM valid'!$T$2:$T$2328,$A3,'Relevant - IN NOW CRM valid'!$G$2:$G$2328,"UK",'Relevant - IN NOW CRM valid'!$M$2:$M$2328,"IT/Systems")+COUNTIFS('Relevant - IN NOW CRM unknown'!$T$2:$T$1227,$A3,'Relevant - IN NOW CRM unknown'!$G$2:$G$1227,"UK",'Relevant - IN NOW CRM unknown'!$M$2:$M$1227,"IT/Systems")+COUNTIFS('Relevant - Not CRM not valid'!$T$2:$T$416,$A3,'Relevant - Not CRM not valid'!$G$2:$G$416,"UK",'Relevant - Not CRM not valid'!$M$2:$M$416,"IT/Systems")+COUNTIFS('Relevant - In CRM not valid'!$T$2:$T$46,$A3,'Relevant - In CRM not valid'!$G$2:$G$46,"UK",'Relevant - In CRM not valid'!$M$2:$M$46,"IT/Systems") -> 1 | L3: =COUNTIFS('Relevant - In CRM valid'!$T$2:$T$4699,$A3,'Relevant - In CRM valid'!$G$2:$G$4699,"UK",'Relevant - In CRM valid'!$M$2:$M$4699,"")+COUNTIFS('Relevant - In CRM unknown'!$T$2:$T$253,$A3,'Relevant - In CRM unknown'!$G$2:$G$253,"UK",'Relevant - In CRM unknown'!$M$2:$M$253,"")+COUNTIFS('Relevant - IN NOW CRM valid'!$T$2:$T$2328,$A3,'Relevant - IN NOW CRM valid'!$G$2:$G$2328,"UK",'Relevant - IN NOW CRM valid'!$M$2:$M$2328,"")+COUNTIFS('Relevant - IN NOW CRM unknown'!$T$2:$T$1227,$A3,'Relevant - IN NOW CRM unknown'!$G$2:$G$1227,"UK",'Relevant - IN NOW CRM unknown'!$M$2:$M$1227,"")+COUNTIFS('Relevant - Not CRM not valid'!$T$2:$T$416,$A3,'Relevant - Not CRM not valid'!$G$2:$G$416,"UK",'Relevant - Not CRM not valid'!$M$2:$M$416,"")+COUNTIFS('Relevant - In CRM not valid'!$T$2:$T$46,$A3,'Relevant - In CRM not valid'!$G$2:$G$46,"UK",'Relevant - In CRM not valid'!$M$2:$M$46,"") -> 0 | M3: =(F3>0)+(J3>0)+(K3>0) -> 3 | N3: =COUNTIFS('Relevant - In CRM valid'!$T$2:$T$4699,$A3,'Relevant - In CRM valid'!$G$2:$G$4699,"UK",'Relevant - In CRM valid'!$Q$2:$Q$4699,"valid")+COUNTIFS('Relevant - In CRM unknown'!$T$2:$T$253,$A3,'Relevant - In CRM unknown'!$G$2:$G$253,"UK",'Relevant - In CRM unknown'!$Q$2:$Q$253,"valid")+COUNTIFS('Relevant - IN NOW CRM valid'!$T$2:$T$2328,$A3,'Relevant - IN NOW CRM valid'!$G$2:$G$2328,"UK",'Relevant - IN NOW CRM valid'!$Q$2:$Q$2328,"valid")+COUNTIFS('Relevant - IN NOW CRM unknown'!$T$2:$T$1227,$A3,'Relevant - IN NOW CRM unknown'!$G$2:$G$1227,"UK",'Relevant - IN NOW CRM unknown'!$Q$2:$Q$1227,"valid")+COUNTIFS('Relevant - Not CRM not valid'!$T$2:$T$416,$A3,'Relevant - Not CRM not valid'!$G$2:$G$416,"UK",'Relevant - Not CRM not valid'!$Q$2:$Q$416,"valid")+COUNTIFS('Relevant - In CRM not valid'!$T$2:$T$46,$A3,'Relevant - In CRM not valid'!$G$2:$G$46,"UK",'Relevant - In CRM not valid'!$Q$2:$Q$46,"valid") -> 155 | O3: =IF(F3=0,"Research ","")&IF(J3=0,"Finance ","")&IF(K3=0,"IT/Systems","")
A4: coventry university | B4: Coventry University | C4: University | D4: =IFERROR(INDEX('UK Target Institutions'!$D$2:$D$727,MATCH($A4,'UK Target Institutions'!$A$2:$A$727,0)),"") -> Yes | E4: =COUNTIFS('Relevant - In CRM valid'!$T$2:$T$4699,$A4,'Relevant - In CRM valid'!$G$2:$G$4699,"UK")+COUNTIFS('Relevant - In CRM unknown'!$T$2:$T$253,$A4,'Relevant - In CRM unknown'!$G$2:$G$253,"UK")+COUNTIFS('Relevant - IN NOW CRM valid'!$T$2:$T$2328,$A4,'Relevant - IN NOW CRM valid'!$G$2:$G$2328,"UK")+COUNTIFS('Relevant - IN NOW CRM unknown'!$T$2:$T$1227,$A4,'Relevant - IN NOW CRM unknown'!$G$2:$G$1227,"UK")+COUNTIFS('Relevant - Not CRM not valid'!$T$2:$T$416,$A4,'Relevant - Not CRM not valid'!$G$2:$G$416,"UK")+COUNTIFS('Relevant - In CRM not valid'!$T$2:$T$46,$A4,'Relevant - In CRM not valid'!$G$2:$G$46,"UK") -> 168 | F4: =COUNTIFS('Relevant - In CRM valid'!$T$2:$T$4699,$A4,'Relevant - In CRM valid'!$G$2:$G$4699,"UK",'Relevant - In CRM valid'!$M$2:$M$4699,"Research")+COUNTIFS('Relevant - In CRM unknown'!$T$2:$T$253,$A4,'Relevant - In CRM unknown'!$G$2:$G$253,"UK",'Relevant - In CRM unknown'!$M$2:$M$253,"Research")+COUNTIFS('Relevant - IN NOW CRM valid'!$T$2:$T$2328,$A4,'Relevant - IN NOW CRM valid'!$G$2:$G$2328,"UK",'Relevant - IN NOW CRM valid'!$M$2:$M$2328,"Research")+COUNTIFS('Relevant - IN NOW CRM unknown'!$T$2:$T$1227,$A4,'Relevant - IN NOW CRM unknown'!$G$2:$G$1227,"UK",'Relevant - IN NOW CRM unknown'!$M$2:$M$1227,"Research")+COUNTIFS('Relevant - Not CRM not valid'!$T$2:$T$416,$A4,'Relevant - Not CRM not valid'!$G$2:$G$416,"UK",'Relevant - Not CRM not valid'!$M$2:$M$416,"Research")+COUNTIFS('Relevant - In CRM not valid'!$T$2:$T$46,$A4,'Relevant - In CRM not valid'!$G$2:$G$46,"UK",'Relevant - In CRM not valid'!$M$2:$M$46,"Research") -> 147 | G4: =COUNTIFS('Relevant - In CRM valid'!$T$2:$T$4699,$A4,'Relevant - In CRM valid'!$G$2:$G$4699,"UK",'Relevant - In CRM valid'!$M$2:$M$4699,"Research",'Relevant - In CRM valid'!$R$2:$R$4699,"Senior")+COUNTIFS('Relevant - In CRM unknown'!$T$2:$T$253,$A4,'Relevant - In CRM unknown'!$G$2:$G$253,"UK",'Relevant - In CRM unknown'!$M$2:$M$253,"Research",'Relevant - In CRM unknown'!$R$2:$R$253,"Senior")+COUNTIFS('Relevant - IN NOW CRM valid'!$T$2:$T$2328,$A4,'Relevant - IN NOW CRM valid'!$G$2:$G$2328,"UK",'Relevant - IN NOW CRM valid'!$M$2:$M$2328,"Research",'Relevant - IN NOW CRM valid'!$R$2:$R$2328,"Senior")+COUNTIFS('Relevant - IN NOW CRM unknown'!$T$2:$T$1227,$A4,'Relevant - IN NOW CRM unknown'!$G$2:$G$1227,"UK",'Relevant - IN NOW CRM unknown'!$M$2:$M$1227,"Research",'Relevant - IN NOW CRM unknown'!$R$2:$R$1227,"Senior")+COUNTIFS('Relevant - Not CRM not valid'!$T$2:$T$416,$A4,'Relevant - Not CRM not valid'!$G$2:$G$416,"UK",'Relevant - Not CRM not valid'!$M$2:$M$416,"Research",'Relevant - Not CRM not valid'!$R$2:$R$416,"Senior")+COUNTIFS('Relevant - In CRM not valid'!$T$2:$T$46,$A4,'Relevant - In CRM not valid'!$G$2:$G$46,"UK",'Relevant - In CRM not valid'!$M$2:$M$46,"Research",'Relevant - In CRM not valid'!$R$2:$R$46,"Senior") -> 59 | H4: =COUNTIFS('Relevant - In CRM valid'!$T$2:$T$4699,$A4,'Relevant - In CRM valid'!$G$2:$G$4699,"UK",'Relevant - In CRM valid'!$M$2:$M$4699,"Research",'Relevant - In CRM valid'!$R$2:$R$4699,"Operational")+COUNTIFS('Relevant - In CRM unknown'!$T$2:$T$253,$A4,'Relevant - In CRM unknown'!$G$2:$G$253,"UK",'Relevant - In CRM unknown'!$M$2:$M$253,"Research",'Relevant - In CRM unknown'!$R$2:$R$253,"Operational")+COUNTIFS('Relevant - IN NOW CRM valid'!$T$2:$T$2328,$A4,'Relevant - IN NOW CRM valid'!$G$2:$G$2328,"UK",'Relevant - IN NOW CRM valid'!$M$2:$M$2328,"Research",'Relevant - IN NOW CRM valid'!$R$2:$R$2328,"Operational")+COUNTIFS('Relevant - IN NOW CRM unknown'!$T$2:$T$1227,$A4,'Relevant - IN NOW CRM unknown'!$G$2:$G$1227,"UK",'Relevant - IN NOW CRM unknown'!$M$2:$M$1227,"Research",'Relevant - IN NOW CRM unknown'!$R$2:$R$1227,"Operational")+COUNTIFS('Relevant - Not CRM not valid'!$T$2:$T$416,$A4,'Relevant - Not CRM not valid'!$G$2:$G$416,"UK",'Relevant - Not CRM not valid'!$M$2:$M$416,"Research",'Relevant - Not CRM not valid'!$R$2:$R$416,"Operational")+COUNTIFS('Relevant - In CRM not valid'!$T$2:$T$46,$A4,'Relevant - In CRM not valid'!$G$2:$G$46,"UK",'Relevant - In CRM not valid'!$M$2:$M$46,"Research",'Relevant - In CRM not valid'!$R$2:$R$46,"Operational") -> 47 | I4: =COUNTIFS('Relevant - In CRM valid'!$T$2:$T$4699,$A4,'Relevant - In CRM valid'!$G$2:$G$4699,"UK",'Relevant - In CRM valid'!$M$2:$M$4699,"Research",'Relevant - In CRM valid'!$R$2:$R$4699,"Academic")+COUNTIFS('Relevant - In CRM unknown'!$T$2:$T$253,$A4,'Relevant - In CRM unknown'!$G$2:$G$253,"UK",'Relevant - In CRM unknown'!$M$2:$M$253,"Research",'Relevant - In CRM unknown'!$R$2:$R$253,"Academic")+COUNTIFS('Relevant - IN NOW CRM valid'!$T$2:$T$2328,$A4,'Relevant - IN NOW CRM valid'!$G$2:$G$2328,"UK",'Relevant - IN NOW CRM valid'!$M$2:$M$2328,"Research",'Relevant - IN NOW CRM valid'!$R$2:$R$2328,"Academic")+COUNTIFS('Relevant - IN NOW CRM unknown'!$T$2:$T$1227,$A4,'Relevant - IN NOW CRM unknown'!$G$2:$G$1227,"UK",'Relevant - IN NOW CRM unknown'!$M$2:$M$1227,"Research",'Relevant - IN NOW CRM unknown'!$R$2:$R$1227,"Academic")+COUNTIFS('Relevant - Not CRM not valid'!$T$2:$T$416,$A4,'Relevant - Not CRM not valid'!$G$2:$G$416,"UK",'Relevant - Not CRM not valid'!$M$2:$M$416,"Research",'Relevant - Not CRM not valid'!$R$2:$R$416,"Academic")+COUNTIFS('Relevant - In CRM not valid'!$T$2:$T$46,$A4,'Relevant - In CRM not valid'!$G$2:$G$46,"UK",'Relevant - In CRM not valid'!$M$2:$M$46,"Research",'Relevant - In CRM not valid'!$R$2:$R$46,"Academic") -> 41 | J4: =COUNTIFS('Relevant - In CRM valid'!$T$2:$T$4699,$A4,'Relevant - In CRM valid'!$G$2:$G$4699,"UK",'Relevant - In CRM valid'!$M$2:$M$4699,"Finance")+COUNTIFS('Relevant - In CRM unknown'!$T$2:$T$253,$A4,'Relevant - In CRM unknown'!$G$2:$G$253,"UK",'Relevant - In CRM unknown'!$M$2:$M$253,"Finance")+COUNTIFS('Relevant - IN NOW CRM valid'!$T$2:$T$2328,$A4,'Relevant - IN NOW CRM valid'!$G$2:$G$2328,"UK",'Relevant - IN NOW CRM valid'!$M$2:$M$2328,"Finance")+COUNTIFS('Relevant - IN NOW CRM unknown'!$T$2:$T$1227,$A4,'Relevant - IN NOW CRM unknown'!$G$2:$G$1227,"UK",'Relevant - IN NOW CRM unknown'!$M$2:$M$1227,"Finance")+COUNTIFS('Relevant - Not CRM not valid'!$T$2:$T$416,$A4,'Relevant - Not CRM not valid'!$G$2:$G$416,"UK",'Relevant - Not CRM not valid'!$M$2:$M$416,"Finance")+COUNTIFS('Relevant - In CRM not valid'!$T$2:$T$46,$A4,'Relevant - In CRM not valid'!$G$2:$G$46,"UK",'Relevant - In CRM not valid'!$M$2:$M$46,"Finance") -> 10 | K4: =COUNTIFS('Relevant - In CRM valid'!$T$2:$T$4699,$A4,'Relevant - In CRM valid'!$G$2:$G$4699,"UK",'Relevant - In CRM valid'!$M$2:$M$4699,"IT/Systems")+COUNTIFS('Relevant - In CRM unknown'!$T$2:$T$253,$A4,'Relevant - In CRM unknown'!$G$2:$G$253,"UK",'Relevant - In CRM unknown'!$M$2:$M$253,"IT/Systems")+COUNTIFS('Relevant - IN NOW CRM valid'!$T$2:$T$2328,$A4,'Relevant - IN NOW CRM valid'!$G$2:$G$2328,"UK",'Relevant - IN NOW CRM valid'!$M$2:$M$2328,"IT/Systems")+COUNTIFS('Relevant - IN NOW CRM unknown'!$T$2:$T$1227,$A4,'Relevant - IN NOW CRM unknown'!$G$2:$G$1227,"UK",'Relevant - IN NOW CRM unknown'!$M$2:$M$1227,"IT/Systems")+COUNTIFS('Relevant - Not CRM not valid'!$T$2:$T$416,$A4,'Relevant - Not CRM not valid'!$G$2:$G$416,"UK",'Relevant - Not CRM not valid'!$M$2:$M$416,"IT/Systems")+COUNTIFS('Relevant - In CRM not valid'!$T$2:$T$46,$A4,'Relevant - In CRM not valid'!$G$2:$G$46,"UK",'Relevant - In CRM not valid'!$M$2:$M$46,"IT/Systems") -> 4 | L4: =COUNTIFS('Relevant - In CRM valid'!$T$2:$T$4699,$A4,'Relevant - In CRM valid'!$G$2:$G$4699,"UK",'Relevant - In CRM valid'!$M$2:$M$4699,"")+COUNTIFS('Relevant - In CRM unknown'!$T$2:$T$253,$A4,'Relevant - In CRM unknown'!$G$2:$G$253,"UK",'Relevant - In CRM unknown'!$M$2:$M$253,"")+COUNTIFS('Relevant - IN NOW CRM valid'!$T$2:$T$2328,$A4,'Relevant - IN NOW CRM valid'!$G$2:$G$2328,"UK",'Relevant - IN NOW CRM valid'!$M$2:$M$2328,"")+COUNTIFS('Relevant - IN NOW CRM unknown'!$T$2:$T$1227,$A4,'Relevant - IN NOW CRM unknown'!$G$2:$G$1227,"UK",'Relevant - IN NOW CRM unknown'!$M$2:$M$1227,"")+COUNTIFS('Relevant - Not CRM not valid'!$T$2:$T$416,$A4,'Relevant - Not CRM not valid'!$G$2:$G$416,"UK",'Relevant - Not CRM not valid'!$M$2:$M$416,"")+COUNTIFS('Relevant - In CRM not valid'!$T$2:$T$46,$A4,'Relevant - In CRM not valid'!$G$2:$G$46,"UK",'Relevant - In CRM not valid'!$M$2:$M$46,"") -> 6 | M4: =(F4>0)+(J4>0)+(K4>0) -> 3 | N4: =COUNTIFS('Relevant - In CRM valid'!$T$2:$T$4699,$A4,'Relevant - In CRM valid'!$G$2:$G$4699,"UK",'Relevant - In CRM valid'!$Q$2:$Q$4699,"valid")+COUNTIFS('Relevant - In CRM unknown'!$T$2:$T$253,$A4,'Relevant - In CRM unknown'!$G$2:$G$253,"UK",'Relevant - In CRM unknown'!$Q$2:$Q$253,"valid")+COUNTIFS('Relevant - IN NOW CRM valid'!$T$2:$T$2328,$A4,'Relevant - IN NOW CRM valid'!$G$2:$G$2328,"UK",'Relevant - IN NOW CRM valid'!$Q$2:$Q$2328,"valid")+COUNTIFS('Relevant - IN NOW CRM unknown'!$T$2:$T$1227,$A4,'Relevant - IN NOW CRM unknown'!$G$2:$G$1227,"UK",'Relevant - IN NOW CRM unknown'!$Q$2:$Q$1227,"valid")+COUNTIFS('Relevant - Not CRM not valid'!$T$2:$T$416,$A4,'Relevant - Not CRM not valid'!$G$2:$G$416,"UK",'Relevant - Not CRM not valid'!$Q$2:$Q$416,"valid")+COUNTIFS('Relevant - In CRM not valid'!$T$2:$T$46,$A4,'Relevant - In CRM not valid'!$G$2:$G$46,"UK",'Relevant - In CRM not valid'!$Q$2:$Q$46,"valid") -> 90 | O4: =IF(F4=0,"Research ","")&IF(J4=0,"Finance ","")&IF(K4=0,"IT/Systems","")
A5: sussex university | B5: University of Sussex | C5: University | D5: =IFERROR(INDEX('UK Target Institutions'!$D$2:$D$727,MATCH($A5,'UK Target Institutions'!$A$2:$A$727,0)),"") -> Yes | E5: =COUNTIFS('Relevant - In CRM valid'!$T$2:$T$4699,$A5,'Relevant - In CRM valid'!$G$2:$G$4699,"UK")+COUNTIFS('Relevant - In CRM unknown'!$T$2:$T$253,$A5,'Relevant - In CRM unknown'!$G$2:$G$253,"UK")+COUNTIFS('Relevant - IN NOW CRM valid'!$T$2:$T$2328,$A5,'Relevant - IN NOW CRM valid'!$G$2:$G$2328,"UK")+COUNTIFS('Relevant - IN NOW CRM unknown'!$T$2:$T$1227,$A5,'Relevant - IN NOW CRM unknown'!$G$2:$G$1227,"UK")+COUNTIFS('Relevant - Not CRM not valid'!$T$2:$T$416,$A5,'Relevant - Not CRM not valid'!$G$2:$G$416,"UK")+COUNTIFS('Relevant - In CRM not valid'!$T$2:$T$46,$A5,'Relevant - In CRM not valid'!$G$2:$G$46,"UK") -> 158 | F5: =COUNTIFS('Relevant - In CRM valid'!$T$2:$T$4699,$A5,'Relevant - In CRM valid'!$G$2:$G$4699,"UK",'Relevant - In CRM valid'!$M$2:$M$4699,"Research")+COUNTIFS('Relevant - In CRM unknown'!$T$2:$T$253,$A5,'Relevant - In CRM unknown'!$G$2:$G$253,"UK",'Relevant - In CRM unknown'!$M$2:$M$253,"Research")+COUNTIFS('Relevant - IN NOW CRM valid'!$T$2:$T$2328,$A5,'Relevant - IN NOW CRM valid'!$G$2:$G$2328,"UK",'Relevant - IN NOW CRM valid'!$M$2:$M$2328,"Research")+COUNTIFS('Relevant - IN NOW CRM unknown'!$T$2:$T$1227,$A5,'Relevant - IN NOW CRM unknown'!$G$2:$G$1227,"UK",'Relevant - IN NOW CRM unknown'!$M$2:$M$1227,"Research")+COUNTIFS('Relevant - Not CRM not valid'!$T$2:$T$416,$A5,'Relevant - Not CRM not valid'!$G$2:$G$416,"UK",'Relevant - Not CRM not valid'!$M$2:$M$416,"Research")+COUNTIFS('Relevant - In CRM not valid'!$T$2:$T$46,$A5,'Relevant - In CRM not valid'!$G$2:$G$46,"UK",'Relevant - In CRM not valid'!$M$2:$M$46,"Research") -> 117 | G5: =COUNTIFS('Relevant - In CRM valid'!$T$2:$T$4699,$A5,'Relevant - In CRM valid'!$G$2:$G$4699,"UK",'Relevant - In CRM valid'!$M$2:$M$4699,"Research",'Relevant - In CRM valid'!$R$2:$R$4699,"Senior")+COUNTIFS('Relevant - In CRM unknown'!$T$2:$T$253,$A5,'Relevant - In CRM unknown'!$G$2:$G$253,"UK",'Relevant - In CRM unknown'!$M$2:$M$253,"Research",'Relevant - In CRM unknown'!$R$2:$R$253,"Senior")+COUNTIFS('Relevant - IN NOW CRM valid'!$T$2:$T$2328,$A5,'Relevant - IN NOW CRM valid'!$G$2:$G$2328,"UK",'Relevant - IN NOW CRM valid'!$M$2:$M$2328,"Research",'Relevant - IN NOW CRM valid'!$R$2:$R$2328,"Senior")+COUNTIFS('Relevant - IN NOW CRM unknown'!$T$2:$T$1227,$A5,'Relevant - IN NOW CRM unknown'!$G$2:$G$1227,"UK",'Relevant - IN NOW CRM unknown'!$M$2:$M$1227,"Research",'Relevant - IN NOW CRM unknown'!$R$2:$R$1227,"Senior")+COUNTIFS('Relevant - Not CRM not valid'!$T$2:$T$416,$A5,'Relevant - Not CRM not valid'!$G$2:$G$416,"UK",'Relevant - Not CRM not valid'!$M$2:$M$416,"Research",'Relevant - Not CRM not valid'!$R$2:$R$416,"Senior")+COUNTIFS('Relevant - In CRM not valid'!$T$2:$T$46,$A5,'Relevant - In CRM not valid'!$G$2:$G$46,"UK",'Relevant - In CRM not valid'!$M$2:$M$46,"Research",'Relevant - In CRM not valid'!$R$2:$R$46,"Senior") -> 33 | H5: =COUNTIFS('Relevant - In CRM valid'!$T$2:$T$4699,$A5,'Relevant - In CRM valid'!$G$2:$G$4699,"UK",'Relevant - In CRM valid'!$M$2:$M$4699,"Research",'Relevant - In CRM valid'!$R$2:$R$4699,"Operational")+COUNTIFS('Relevant - In CRM unknown'!$T$2:$T$253,$A5,'Relevant - In CRM unknown'!$G$2:$G$253,"UK",'Relevant - In CRM unknown'!$M$2:$M$253,"Research",'Relevant - In CRM unknown'!$R$2:$R$253,"Operational")+COUNTIFS('Relevant - IN NOW CRM valid'!$T$2:$T$2328,$A5,'Relevant - IN NOW CRM valid'!$G$2:$G$2328,"UK",'Relevant - IN NOW CRM valid'!$M$2:$M$2328,"Research",'Relevant - IN NOW CRM valid'!$R$2:$R$2328,"Operational")+COUNTIFS('Relevant - IN NOW CRM unknown'!$T$2:$T$1227,$A5,'Relevant - IN NOW CRM unknown'!$G$2:$G$1227,"UK",'Relevant - IN NOW CRM unknown'!$M$2:$M$1227,"Research",'Relevant - IN NOW CRM unknown'!$R$2:$R$1227,"Operational")+COUNTIFS('Relevant - Not CRM not valid'!$T$2:$T$416,$A5,'Relevant - Not CRM not valid'!$G$2:$G$416,"UK",'Relevant - Not CRM not valid'!$M$2:$M$416,"Research",'Relevant - Not CRM not valid'!$R$2:$R$416,"Operational")+COUNTIFS('Relevant - In CRM not valid'!$T$2:$T$46,$A5,'Relevant - In CRM not valid'!$G$2:$G$46,"UK",'Relevant - In CRM not valid'!$M$2:$M$46,"Research",'Relevant - In CRM not valid'!$R$2:$R$46,"Operational") -> 76 | I5: =COUNTIFS('Relevant - In CRM valid'!$T$2:$T$4699,$A5,'Relevant - In CRM valid'!$G$2:$G$4699,"UK",'Relevant - In CRM valid'!$M$2:$M$4699,"Research",'Relevant - In CRM valid'!$R$2:$R$4699,"Academic")+COUNTIFS('Relevant - In CRM unknown'!$T$2:$T$253,$A5,'Relevant - In CRM unknown'!$G$2:$G$253,"UK",'Relevant - In CRM unknown'!$M$2:$M$253,"Research",'Relevant - In CRM unknown'!$R$2:$R$253,"Academic")+COUNTIFS('Relevant - IN NOW CRM valid'!$T$2:$T$2328,$A5,'Relevant - IN NOW CRM valid'!$G$2:$G$2328,"UK",'Relevant - IN NOW CRM valid'!$M$2:$M$2328,"Research",'Relevant - IN NOW CRM valid'!$R$2:$R$2328,"Academic")+COUNTIFS('Relevant - IN NOW CRM unknown'!$T$2:$T$1227,$A5,'Relevant - IN NOW CRM unknown'!$G$2:$G$1227,"UK",'Relevant - IN NOW CRM unknown'!$M$2:$M$1227,"Research",'Relevant - IN NOW CRM unknown'!$R$2:$R$1227,"Academic")+COUNTIFS('Relevant - Not CRM not valid'!$T$2:$T$416,$A5,'Relevant - Not CRM not valid'!$G$2:$G$416,"UK",'Relevant - Not CRM not valid'!$M$2:$M$416,"Research",'Relevant - Not CRM not valid'!$R$2:$R$416,"Academic")+COUNTIFS('Relevant - In CRM not valid'!$T$2:$T$46,$A5,'Relevant - In CRM not valid'!$G$2:$G$46,"UK",'Relevant - In CRM not valid'!$M$2:$M$46,"Research",'Relevant - In CRM not valid'!$R$2:$R$46,"Academic") -> 4 | J5: =COUNTIFS('Relevant - In CRM valid'!$T$2:$T$4699,$A5,'Relevant - In CRM valid'!$G$2:$G$4699,"UK",'Relevant - In CRM valid'!$M$2:$M$4699,"Finance")+COUNTIFS('Relevant - In CRM unknown'!$T$2:$T$253,$A5,'Relevant - In CRM unknown'!$G$2:$G$253,"UK",'Relevant - In CRM unknown'!$M$2:$M$253,"Finance")+COUNTIFS('Relevant - IN NOW CRM valid'!$T$2:$T$2328,$A5,'Relevant - IN NOW CRM valid'!$G$2:$G$2328,"UK",'Relevant - IN NOW CRM valid'!$M$2:$M$2328,"Finance")+COUNTIFS('Relevant - IN NOW CRM unknown'!$T$2:$T$1227,$A5,'Relevant - IN NOW CRM unknown'!$G$2:$G$1227,"UK",'Relevant - IN NOW CRM unknown'!$M$2:$M$1227,"Finance")+COUNTIFS('Relevant - Not CRM not valid'!$T$2:$T$416,$A5,'Relevant - Not CRM not valid'!$G$2:$G$416,"UK",'Relevant - Not CRM not valid'!$M$2:$M$416,"Finance")+COUNTIFS('Relevant - In CRM not valid'!$T$2:$T$46,$A5,'Relevant - In CRM not valid'!$G$2:$G$46,"UK",'Relevant - In CRM not valid'!$M$2:$M$46,"Finance") -> 22 | K5: =COUNTIFS('Relevant - In CRM valid'!$T$2:$T$4699,$A5,'Relevant - In CRM valid'!$G$2:$G$4699,"UK",'Relevant - In CRM valid'!$M$2:$M$4699,"IT/Systems")+COUNTIFS('Relevant - In CRM unknown'!$T$2:$T$253,$A5,'Relevant - In CRM unknown'!$G$2:$G$253,"UK",'Relevant - In CRM unknown'!$M$2:$M$253,"IT/Systems")+COUNTIFS('Relevant - IN NOW CRM valid'!$T$2:$T$2328,$A5,'Relevant - IN NOW CRM valid'!$G$2:$G$2328,"UK",'Relevant - IN NOW CRM valid'!$M$2:$M$2328,"IT/Systems")+COUNTIFS('Relevant - IN NOW CRM unknown'!$T$2:$T$1227,$A5,'Relevant - IN NOW CRM unknown'!$G$2:$G$1227,"UK",'Relevant - IN NOW CRM unknown'!$M$2:$M$1227,"IT/Systems")+COUNTIFS('Relevant - Not CRM not valid'!$T$2:$T$416,$A5,'Relevant - Not CRM not valid'!$G$2:$G$416,"UK",'Relevant - Not CRM not valid'!$M$2:$M$416,"IT/Systems")+COUNTIFS('Relevant - In CRM not valid'!$T$2:$T$46,$A5,'Relevant - In CRM not valid'!$G$2:$G$46,"UK",'Relevant - In CRM not valid'!$M$2:$M$46,"IT/Systems") -> 4 | L5: =COUNTIFS('Relevant - In CRM valid'!$T$2:$T$4699,$A5,'Relevant - In CRM valid'!$G$2:$G$4699,"UK",'Relevant - In CRM valid'!$M$2:$M$4699,"")+COUNTIFS('Relevant - In CRM unknown'!$T$2:$T$253,$A5,'Relevant - In CRM unknown'!$G$2:$G$253,"UK",'Relevant - In CRM unknown'!$M$2:$M$253,"")+COUNTIFS('Relevant - IN NOW CRM valid'!$T$2:$T$2328,$A5,'Relevant - IN NOW CRM valid'!$G$2:$G$2328,"UK",'Relevant - IN NOW CRM valid'!$M$2:$M$2328,"")+COUNTIFS('Relevant - IN NOW CRM unknown'!$T$2:$T$1227,$A5,'Relevant - IN NOW CRM unknown'!$G$2:$G$1227,"UK",'Relevant - IN NOW CRM unknown'!$M$2:$M$1227,"")+COUNTIFS('Relevant - Not CRM not valid'!$T$2:$T$416,$A5,'Relevant - Not CRM not valid'!$G$2:$G$416,"UK",'Relevant - Not CRM not valid'!$M$2:$M$416,"")+COUNTIFS('Relevant - In CRM not valid'!$T$2:$T$46,$A5,'Relevant - In CRM not valid'!$G$2:$G$46,"UK",'Relevant - In CRM not valid'!$M$2:$M$46,"") -> 13 | M5: =(F5>0)+(J5>0)+(K5>0) -> 3 | N5: =COUNTIFS('Relevant - In CRM valid'!$T$2:$T$4699,$A5,'Relevant - In CRM valid'!$G$2:$G$4699,"UK",'Relevant - In CRM valid'!$Q$2:$Q$4699,"valid")+COUNTIFS('Relevant - In CRM unknown'!$T$2:$T$253,$A5,'Relevant - In CRM unknown'!$G$2:$G$253,"UK",'Relevant - In CRM unknown'!$Q$2:$Q$253,"valid")+COUNTIFS('Relevant - IN NOW CRM valid'!$T$2:$T$2328,$A5,'Relevant - IN NOW CRM valid'!$G$2:$G$2328,"UK",'Relevant - IN NOW CRM valid'!$Q$2:$Q$2328,"valid")+COUNTIFS('Relevant - IN NOW CRM unknown'!$T$2:$T$1227,$A5,'Relevant - IN NOW CRM unknown'!$G$2:$G$1227,"UK",'Relevant - IN NOW CRM unknown'!$Q$2:$Q$1227,"valid")+COUNTIFS('Relevant - Not CRM not valid'!$T$2:$T$416,$A5,'Relevant - Not CRM not valid'!$G$2:$G$416,"UK",'Relevant - Not CRM not valid'!$Q$2:$Q$416,"valid")+COUNTIFS('Relevant - In CRM not valid'!$T$2:$T$46,$A5,'Relevant - In CRM not valid'!$G$2:$G$46,"UK",'Relevant - In CRM not valid'!$Q$2:$Q$46,"valid") -> 39 | O5: =IF(F5=0,"Research ","")&IF(J5=0,"Finance ","")&IF(K5=0,"IT/Systems","")
